<?xml version="1.0"?>
<robot name="semitrailer" xmlns:xacro="http://ros.org/wiki/xacro">
  <xacro:property name="props_yaml" value="$(arg props_yaml)" />
  <xacro:property name="props" value="${xacro.load_yaml(props_yaml)}" />
  <xacro:property name="wheel_radius" value="${props['wheel_radius']}" />
  <xacro:property name="wheel_width" value="${props['wheel_width']}" />
  <xacro:property name="trailer_length" value="${props['trailer_length']}" />
  <xacro:property name="trailer_width" value="${props['trailer_width']}" />
  <xacro:property name="trailer_height" value="${props['trailer_height']}" />
  <xacro:property name="hitch_length" value="${props['hitch_length']}" />
  <xacro:property name="tractor_length" value="${props['tractor_length']}" />
  <xacro:property name="tractor_width" value="${props['tractor_width']}" />
  <xacro:property name="tractor_height" value="${props['tractor_height']}" />

  <xacro:include filename="$(find semitrailer_description)/urdf/material.urdf" />
  <xacro:include filename="$(find semitrailer_description)/urdf/wheel.urdf" />

  <link name="base_footprint" />

  <joint name="base_joint" type="fixed">
    <parent link="base_footprint" />
    <child link="base_link" />
    <origin xyz="0 0 ${wheel_radius}" />
  </joint>

  <link name="base_link" />

  <joint name="trailer_joint" type="fixed">
    <parent link="base_link" />
    <child link="trailer_link" />
    <origin xyz="${trailer_length / 2} 0 0" />
  </joint>

  <link name="trailer_link">
    <visual>
      <origin xyz="0 0 ${trailer_height / 2}" />
      <geometry>
        <box size="${trailer_length} ${trailer_width} ${trailer_height}" />
      </geometry>
      <material name="Blue" />
    </visual>
  </link>

  <xacro:wheel prefix="trailer_left" parent="trailer_link" radius="${wheel_radius}"
    width="${wheel_width}">
    <origin xyz="${-trailer_length / 2} ${trailer_width / 2} 0" rpy="${-radians(90)} 0 0" />
    <axis xyz="0 0 1" />
  </xacro:wheel>

  <xacro:wheel prefix="trailer_right" parent="trailer_link" radius="${wheel_radius}"
    width="${wheel_width}">
    <origin xyz="${-trailer_length / 2} ${-trailer_width / 2} 0" rpy="${radians(90)} 0 0" />
    <axis xyz="0 0 1" />
  </xacro:wheel>

  <joint name="coupler_joint" type="continuous">
    <parent link="trailer_link" />
    <child link="coupler_link" />
    <origin xyz="${trailer_length / 2} 0 0" />
    <axis xyz="0 0 1" />
  </joint>

  <link name="coupler_link" />

  <joint name="tractor_joint" type="fixed">
    <parent link="coupler_link" />
    <child link="tractor_link" />
    <origin xyz="${hitch_length + tractor_length / 2} 0 0" />
  </joint>

  <link name="tractor_link">
    <visual>
      <origin xyz="0 0 ${tractor_height / 2}" />
      <geometry>
        <box size="${tractor_length} ${tractor_width} ${tractor_height}" />
      </geometry>
      <material name="Orange" />
    </visual>
  </link>

  <xacro:wheel prefix="tractor_rear_left" parent="tractor_link" radius="${wheel_radius}"
    width="${wheel_width}">
    <origin xyz="${-tractor_length / 2} ${tractor_width / 2} 0" rpy="${-radians(90)} 0 0" />
    <axis xyz="0 0 1" />
  </xacro:wheel>

  <xacro:wheel prefix="tractor_rear_right" parent="tractor_link" radius="${wheel_radius}"
    width="${wheel_width}">
    <origin xyz="${-tractor_length / 2} ${-tractor_width / 2} 0" rpy="${radians(90)} 0 0" />
    <axis xyz="0 0 1" />
  </xacro:wheel>

  <joint name="tractor_steering_joint" type="continuous">
    <parent link="tractor_link" />
    <child link="tractor_steering_link" />
    <origin xyz="${tractor_length / 2} 0 0" />
    <axis xyz="0 0 1" />
  </joint>

  <link name="tractor_steering_link" />

  <xacro:wheel prefix="tractor_front_left" parent="tractor_steering_link" radius="${wheel_radius}"
    width="${wheel_width}">
    <origin xyz="0 ${tractor_width / 2} 0" rpy="${-radians(90)} 0 0" />
    <axis xyz="0 0 1" />
  </xacro:wheel>

  <xacro:wheel prefix="tractor_front_right" parent="tractor_steering_link" radius="${wheel_radius}"
    width="${wheel_width}">
    <origin xyz="0 ${-tractor_width / 2} 0" rpy="${radians(90)} 0 0" />
    <axis xyz="0 0 1" />
  </xacro:wheel>
</robot>